Workbook

Sheet Main
B1: b | C1: l | D1: d | E1: Q | F1: cos3Q | G1: Ecoll [%] | H1: Esum [%] | I1: p | J1: leff | K1: deff | L1: Rint | M1: Rcoll | N1: Rsyst | O1: Simulation Spatial R | P1: theta | Q1: x | R1: k | S1: Ld | T1: Td | U1: t
A2: Definitions | B2: distance from center of hole to center of heart | C2: length of collimator | D2: length of sides of hole | E2: angle from axis | G2: senstivitiy of individual systems | H2: summation of all Ecoll | I2: pixel size | J2: effective length of collimator | K2: effective length of sides of hole | L2: intrinsic resolution of collimator | M2: resolution of collimator | N2: resolution of individual detector systems | O2: average of all Rsyst | P2: acceptance angle of collimator | Q2: focal length of collimator minus length of collimator | R2: length of side of guide at exit | S2: length of side of detector crystal | T2: thickness of detector crystal | U2: thickness of collimator wall
A3: 1 | B3: =Coordinates!E3 -> 294.25721 | C3: =((S3/2)/(TAN(RADIANS(P3))))-Q3 -> 89.070206 | D3: 2.3 | E3: 0 | F3: =COS(E3)^3 -> 1 | G3: =100*(K3*K3*F3/(16*B3*B3)) -> 0.00041740315 | H3: =SUM(G3:G82) -> 0.060564199 | I3: =Values!T3 -> 2 | J3: =C3-0.8 -> 88.270206 | K3: =SQRT(D3*(D3+((2*TAN(RADIANS(P3)))/2.5))) -> 2.4047224 | L3: =I3 -> 2 | M3: =K3*(B3+C3)/C3 -> 10.349095 | N3: =SQRT(L3*L3+M3*M3) -> 10.540577 | O3: =AVERAGE(N3:N83) -> 10.91574 | P3: =Coordinates!AG3 -> 14.990223 | Q3: =(D3/2)/(TAN(RADIANS(P3))) -> 4.2947898 | R3: =(((TAN(RADIANS(Coordinates!AH3)))*3)*2)+D3 -> 4.0615318 | S3: 50 | T3: 10 | U3: 2
A4: 2 | B4: =Coordinates!E4 -> 274.65173 | C4: =((S4/2)/(TAN(RADIANS(P4))))-Q4 -> 82.700811 | D4: 2.3 | E4: 0 | F4: =COS(E4)^3 -> 1 | G4: =100*(K4*K4*F4/(16*B4*B4)) -> 0.000482265 | I4: =Values!T4 -> 2 | J4: =C4-0.8 -> 81.900811 | K4: =SQRT(D4*(D4+((2*TAN(RADIANS(P4)))/2.5))) -> 2.4125994 | L4: =I4 -> 2 | M4: =K4*(B4+C4)/C4 -> 10.42491 | N4: =SQRT(L4*L4+M4*M4) -> 10.615025 | P4: =Coordinates!AG4 -> 16.086977 | Q4: =(D4/2)/(TAN(RADIANS(P4))) -> 3.9876702 | R4: =(((TAN(RADIANS(Coordinates!AH4)))*3)*2)+D4 -> 4.1972002 | S4: 50 | T4: 10 | U4: 2
A5: 3 | B5: =Coordinates!E5 -> 253.46752 | C5: =((S5/2)/(TAN(RADIANS(P5))))-Q5 -> 75.776076 | D5: 2.3 | E5: 0 | F5: =COS(E5)^3 -> 1 | G5: =100*(K5*K5*F5/(16*B5*B5)) -> 0.00057096426 | I5: =Values!T5 -> 2 | J5: =C5-0.8 -> 74.976076 | K5: =SQRT(D5*(D5+((2*TAN(RADIANS(P5)))/2.5))) -> 2.4226282 | L5: =I5 -> 2 | M5: =K5*(B5+C5)/C5 -> 10.526209 | N5: =SQRT(L5*L5+M5*M5) -> 10.714526 | P5: =Coordinates!AG5 -> 17.471038 | Q5: =(D5/2)/(TAN(RADIANS(P5))) -> 3.653773 | R5: =(((TAN(RADIANS(Coordinates!AH5)))*3)*2)+D5 -> 4.3705744 | S5: 50 | T5: 10 | U5: 2
A6: 4 | B6: =Coordinates!E6 -> 232.73109 | C6: =((S6/2)/(TAN(RADIANS(P6))))-Q6 -> 68.942582 | D6: 2.3 | E6: 0 | F6: =COS(E6)^3 -> 1 | G6: =100*(K6*K6*F6/(16*B6*B6)) -> 0.00068386702 | I6: =Values!T6 -> 2 | J6: =C6-0.8 -> 68.142582 | K6: =SQRT(D6*(D6+((2*TAN(RADIANS(P6)))/2.5))) -> 2.4344465 | L6: =I6 -> 2 | M6: =K6*(B6+C6)/C6 -> 10.652465 | N6: =SQRT(L6*L6+M6*M6) -> 10.838589 | P6: =Coordinates!AG6 -> 19.082552 | Q6: =(D6/2)/(TAN(RADIANS(P6))) -> 3.3242755 | R6: =(((TAN(RADIANS(Coordinates!AH6)))*3)*2)+D6 -> 4.5758068 | S6: 50 | T6: 10 | U6: 2
A7: 5 | B7: =Coordinates!E7 -> 214.37084 | C7: =((S7/2)/(TAN(RADIANS(P7))))-Q7 -> 62.832246 | D7: 2.3 | E7: 0 | F7: =COS(E7)^3 -> 1 | G7: =100*(K7*K7*F7/(16*B7*B7)) -> 0.00081444479 | I7: =Values!T7 -> 2 | J7: =C7-0.8 -> 62.032246 | K7: =SQRT(D7*(D7+((2*TAN(RADIANS(P7)))/2.5))) -> 2.4471271 | L7: =I7 -> 2 | M7: =K7*(B7+C7)/C7 -> 10.796227 | N7: =SQRT(L7*L7+M7*M7) -> 10.979914 | P7: =Coordinates!AG7 -> 20.785869 | Q7: =(D7/2)/(TAN(RADIANS(P7))) -> 3.0296471 | R7: =(((TAN(RADIANS(Coordinates!AH7)))*3)*2)+D7 -> 4.7971254 | S7: 50 | T7: 10 | U7: 2
A8: 6 | B8: =Coordinates!E8 -> 199.93875 | C8: =((S8/2)/(TAN(RADIANS(P8))))-Q8 -> 57.97763 | D8: 2.3 | E8: 0 | F8: =COS(E8)^3 -> 1 | G8: =100*(K8*K8*F8/(16*B8*B8)) -> 0.00094540909 | I8: =Values!T8 -> 2 | J8: =C8-0.8 -> 57.17763 | K8: =SQRT(D8*(D8+((2*TAN(RADIANS(P8)))/2.5))) -> 2.4590471 | L8: =I8 -> 2 | M8: =K8*(B8+C8)/C8 -> 10.939194 | N8: =SQRT(L8*L8+M8*M8) -> 11.12052 | P8: =Coordinates!AG8 -> 22.360578 | Q8: =(D8/2)/(TAN(RADIANS(P8))) -> 2.7955671 | R8: =(((TAN(RADIANS(Coordinates!AH8)))*3)*2)+D8 -> 5.0062162 | S8: 50 | T8: 10 | U8: 2
A9: 7 | B9: =Coordinates!E9 -> 190.57444 | C9: =((S9/2)/(TAN(RADIANS(P9))))-Q9 -> 54.797151 | D9: 2.3 | E9: 0 | F9: =COS(E9)^3 -> 1 | G9: =100*(K9*K9*F9/(16*B9*B9)) -> 0.0010481616 | I9: =Values!T9 -> 2 | J9: =C9-0.8 -> 53.997151 | K9: =SQRT(D9*(D9+((2*TAN(RADIANS(P9)))/2.5))) -> 2.4679636 | L9: =I9 -> 2 | M9: =K9*(B9+C9)/C9 -> 11.051088 | N9: =SQRT(L9*L9+M9*M9) -> 11.230608 | P9: =Coordinates!AG9 -> 23.520679 | Q9: =(D9/2)/(TAN(RADIANS(P9))) -> 2.6422106 | R9: =(((TAN(RADIANS(Coordinates!AH9)))*3)*2)+D9 -> 5.1632875 | S9: 50 | T9: 10 | U9: 2
A10: 8 | B10: =Coordinates!E10 -> 186.9885 | C10: =((S10/2)/(TAN(RADIANS(P10))))-Q10 -> 53.571762 | D10: 2.3 | E10: 0 | F10: =COS(E10)^3 -> 1 | G10: =100*(K10*K10*F10/(16*B10*B10)) -> 0.0010920234 | I10: =Values!T10 -> 2 | J10: =C10-0.8 -> 52.771762 | K10: =SQRT(D10*(D10+((2*TAN(RADIANS(P10)))/2.5))) -> 2.4716721 | L10: =I10 -> 2 | M10: =K10*(B10+C10)/C10 -> 11.098871 | N10: =SQRT(L10*L10+M10*M10) -> 11.27763 | P10: =Coordinates!AG10 -> 23.998496 | Q10: =(D10/2)/(TAN(RADIANS(P10))) -> 2.5831248 | R10: =(((TAN(RADIANS(Coordinates!AH10)))*3)*2)+D10 -> 5.2287818 | S10: 50 | T10: 10 | U10: 2
A11: 9 | B11: =Coordinates!E11 -> 189.43283 | C11: =((S11/2)/(TAN(RADIANS(P11))))-Q11 -> 54.407518 | D11: 2.3 | E11: 0 | F11: =COS(E11)^3 -> 1 | G11: =100*(K11*K11*F11/(16*B11*B11)) -> 0.0010618319 | I11: =Values!T11 -> 2 | J11: =C11-0.8 -> 53.607518 | K11: =SQRT(D11*(D11+((2*TAN(RADIANS(P11)))/2.5))) -> 2.4691253 | L11: =I11 -> 2 | M11: =K11*(B11+C11)/C11 -> 11.065978 | N11: =SQRT(L11*L11+M11*M11) -> 11.245259 | P11: =Coordinates!AG11 -> 23.670652 | Q11: =(D11/2)/(TAN(RADIANS(P11))) -> 2.6234233 | R11: =(((TAN(RADIANS(Coordinates!AH11)))*3)*2)+D11 -> 5.1837926 | S11: 50 | T11: 10 | U11: 2
A12: 10 | B12: =Coordinates!E12 -> 196.99023 | C12: =((S12/2)/(TAN(RADIANS(P12))))-Q12 -> 56.97906 | D12: 2.3 | E12: 0 | F12: =COS(E12)^3 -> 1 | G12: =100*(K12*K12*F12/(16*B12*B12)) -> 0.00097605887 | I12: =Values!T12 -> 2 | J12: =C12-0.8 -> 56.17906 | K12: =SQRT(D12*(D12+((2*TAN(RADIANS(P12)))/2.5))) -> 2.4617428 | L12: =I12 -> 2 | M12: =K12*(B12+C12)/C12 -> 10.972576 | N12: =SQRT(L12*L12+M12*M12) -> 11.153359 | P12: =Coordinates!AG12 -> 22.712958 | Q12: =(D12/2)/(TAN(RADIANS(P12))) -> 2.747418 | R12: =(((TAN(RADIANS(Coordinates!AH12)))*3)*2)+D12 -> 5.0536432 | S12: 50 | T12: 10 | U12: 2
A13: 11 | B13: =Coordinates!E13 -> 208.13662 | C13: =((S13/2)/(TAN(RADIANS(P13))))-Q13 -> 60.741525 | D13: 2.3 | E13: 0 | F13: =COS(E13)^3 -> 1 | G13: =100*(K13*K13*F13/(16*B13*B13)) -> 0.00086743318 | I13: =Values!T13 -> 2 | J13: =C13-0.8 -> 59.941525 | K13: =SQRT(D13*(D13+((2*TAN(RADIANS(P13)))/2.5))) -> 2.4520341 | L13: =I13 -> 2 | M13: =K13*(B13+C13)/C13 -> 10.854162 | N13: =SQRT(L13*L13+M13*M13) -> 11.036886 | P13: =Coordinates!AG13 -> 21.437324 | Q13: =(D13/2)/(TAN(RADIANS(P13))) -> 2.9288366 | R13: =(((TAN(RADIANS(Coordinates!AH13)))*3)*2)+D13 -> 4.8830764 | S13: 50 | T13: 10 | U13: 2
A14: 12 | B14: =Coordinates!E14 -> 220.94817 | C14: =((S14/2)/(TAN(RADIANS(P14))))-Q14 -> 65.028733 | D14: 2.3 | E14: 0 | F14: =COS(E14)^3 -> 1 | G14: =100*(K14*K14*F14/(16*B14*B14)) -> 0.00076365642 | I14: =Values!T14 -> 2 | J14: =C14-0.8 -> 64.228733 | K14: =SQRT(D14*(D14+((2*TAN(RADIANS(P14)))/2.5))) -> 2.4423022 | L14: =I14 -> 2 | M14: =K14*(B14+C14)/C14 -> 10.740514 | N14: =SQRT(L14*L14+M14*M14) -> 10.925138 | P14: =Coordinates!AG14 -> 20.141065 | Q14: =(D14/2)/(TAN(RADIANS(P14))) -> 3.1355574 | R14: =(((TAN(RADIANS(Coordinates!AH14)))*3)*2)+D14 -> 4.7127796 | S14: 50 | T14: 10 | U14: 2
A15: 13 | B15: =Coordinates!E15 -> 233.33339 | C15: =((S15/2)/(TAN(RADIANS(P15))))-Q15 -> 69.141984 | D15: 2.3 | E15: 0 | F15: =COS(E15)^3 -> 1 | G15: =100*(K15*K15*F15/(16*B15*B15)) -> 0.00068013034 | I15: =Values!T15 -> 2 | J15: =C15-0.8 -> 68.341984 | K15: =SQRT(D15*(D15+((2*TAN(RADIANS(P15)))/2.5))) -> 2.4340694 | L15: =I15 -> 2 | M15: =K15*(B15+C15)/C15 -> 10.648321 | N15: =SQRT(L15*L15+M15*M15) -> 10.834517 | P15: =Coordinates!AG15 -> 19.031484 | Q15: =(D15/2)/(TAN(RADIANS(P15))) -> 3.3338902 | R15: =(((TAN(RADIANS(Coordinates!AH15)))*3)*2)+D15 -> 4.5692435 | S15: 50 | T15: 10 | U15: 2
... A82: 80 | B82: =Coordinates!E82 -> 263.34405 | C82: =((S82/2)/(TAN(RADIANS(P82))))-Q82 -> 79.010721 | D82: 2.3 | E82: 0 | F82: =COS(E82)^3 -> 1 | G82: =100*(K82*K82*F82/(16*B82*B82)) -> 0.00052680341 | I82: =Values!T82 -> 2 | J82: =C82-0.8 -> 78.210721 | K82: =SQRT(D82*(D82+((2*TAN(RADIANS(P82)))/2.5))) -> 2.41773 | L82: =I82 -> 2 | M82: =K82*(B82+C82)/C82 -> 10.476065 | N82: =SQRT(L82*L82+M82*M82) -> 10.665267 | P82: =Coordinates!AG82 -> 16.796848 | Q82: =(D82/2)/(TAN(RADIANS(P82))) -> 3.8097412 | R82: =(((TAN(RADIANS(Coordinates!AH82)))*3)*2)+D82 -> 4.2858065 | S82: 50 | T82: 10 | U82: 2

Sheet Coordinates
B1: x1 | C1: y1 | D1: z1 | E1: b | F1: S | G1: l | H1: l + b+Td | I1: x2 | J1: y2 | K1: z2 | O1: (l + b+Td)/2 | P1: xm | Q1: ym | R1: zm | S1: FR calc | T1: ϕ1 | U1: SR calc | V1: ϕ2
A2: Definitions | B2: x coordinate value at center of hole | C2: y coordinate value at center of hole | D2: z coordinate value at center of hole | E2: distance from center of hole to center of heart | F2: 3D slope | G2: length of collimator | I2: x coordinate value at end of detector | J2: y coordinate value at end of detector | K2: z coordinate value at end of detector | L2: x coordinate value at exposed face of scintillator | M2: y coordinate value at exposed face of scintillator | N2: z coordinate value at exposed face of scintillator | P2: x coordinate value at center point of system | Q2: y coordinate value at center point of system | R2: z coordinate value at center point of system | S2: Calculator for first rotation | T2: Rotation around z axis of GATE geometry | U2: Calculator for second rotation | V2: Rotation around x axis of GATE geometry | X2: pinhole range | Y2: pinhole azimuth (radians) | Z2: pinhole elevation (radians) | AA2: pinhole outer edge range | AB2: pinhole outer edge height | AC2: pinhole outer edge elevation (radians) | AD2: pinhole outer edge radius | AE2: RoI radius | AF2: pinhole outer edge angle (radians) | AG2: theta (degrees) | AH2: exit angle (degrees) | AJ2: Crystal Pitch
A3: 1 | B3: ='MDSL cloud import'!C3 -> 277.002 | C3: ='MDSL cloud import'!D3 -> 70.37124 | D3: ='MDSL cloud import'!E3 -> -70.0363 | E3: =SQRT((B3^2)+(C3^2)+(D3^2)) -> 294.25721 | F3: =SQRT((1)+((C3/B3)^2)+(D3/B3)^2) -> 1.0622927 | G3: =Main!C3 -> 89.070206 | H3: =E3+G3+Main!T3 -> 393.32741 | I3: =H3/F3*SIGN(B3) -> 370.26274 | J3: =I3*C3/B3 -> 94.063755 | K3: =I3*D3/B3 -> -93.616048 | L3: =(H3-Main!T3)/F3*SIGN(B3) -> 360.84914 | M3: =L3*C3/B3 -> 91.672268 | N3: =L3*D3/B3 -> -91.235943 | O3: =(H3)/2 -> 196.66371 | P3: =O3/F3*SIGN(B3) -> 185.13137 | Q3: =P3*C3/B3 -> 47.031878 | R3: =P3*D3/B3 -> -46.808024 | S3: =DEGREES(ATAN((ABS(C3))/(ABS(B3)))) -> 14.254215 | T3: =S3+180 -> 194.25422 | U3: =90-DEGREES(ACOS(ABS(D3/E3))) -> 13.769147 | V3: =-U3 -> -13.769147 | X3: =SQRT(SUMSQ(B3,C3)) -> 285.80101 | Y3: =(ATAN2(B3,C3)) -> 0.24878299 | Z3: =(ATAN2(X3,D3)) -> -0.24031695 | AA3: =-Main!D3/2*SIN(ABS(Z3))+X3 -> 285.5273 | AB3: =Main!D3/2*COS(ABS(Z3))*SIGN(Z3)+D3 -> -71.153252 | AC3: =ATAN2(AA3,AB3) -> -0.24422508 | AD3: =SQRT(SUMSQ(AA3,AB3)) -> 294.25945 | AE3: ='MDSL cloud import'!H2/2 -> 75 | AF3: =(ASIN(AE3/AD3)) -> 0.25772062 | AG3: =DEGREES(AF3+ABS(AC3-Z3)) -> 14.990223 | AH3: =DEGREES(ATAN((Main!S3/2+Main!D3/2)/Main!C3)) -> 16.361639 | AI3: =A3 -> 1 | AJ3: =Main!S3*(G3-Main!T3)/G3/25 -> 1.775458 | AK3: Value filled in from CAD | AP3: z
A4: 2 | B4: ='MDSL cloud import'!C4 -> 242.8831 | C4: ='MDSL cloud import'!D4 -> 107.2608 | D4: ='MDSL cloud import'!E4 -> -70.2602 | E4: =SQRT((B4^2)+(C4^2)+(D4^2)) -> 274.65173 | F4: =SQRT((1)+((C4/B4)^2)+(D4/B4)^2) -> 1.130798 | G4: =Main!C4 -> 82.700811 | H4: =E4+G4+Main!T4 -> 367.35255 | I4: =H4/F4*SIGN(B4) -> 324.86132 | J4: =I4*C4/B4 -> 143.46361 | K4: =I4*D4/B4 -> -93.974514 | L4: =(H4-Main!T4)/F4*SIGN(B4) -> 316.01801 | M4: =L4*C4/B4 -> 139.55827 | N4: =L4*D4/B4 -> -91.416358 | O4: =(H4)/2 -> 183.67627 | P4: =O4/F4*SIGN(B4) -> 162.43066 | Q4: =P4*C4/B4 -> 71.731803 | R4: =P4*D4/B4 -> -46.987257 | S4: =DEGREES(ATAN((ABS(C4))/(ABS(B4)))) -> 23.826968 | T4: =S4+180 -> 203.82697 | U4: =90-DEGREES(ACOS(ABS(D4/E4))) -> 14.821919 | V4: =-U4 -> -14.821919 | X4: =SQRT(SUMSQ(B4,C4)) -> 265.51286 | Y4: =(ATAN2(B4,C4)) -> 0.41585905 | Z4: =(ATAN2(X4,D4)) -> -0.25869129 | AA4: =-Main!D4/2*SIN(ABS(Z4))+X4 -> 265.21867 | AB4: =Main!D4/2*COS(ABS(Z4))*SIGN(Z4)+D4 -> -71.371934 | AC4: =ATAN2(AA4,AB4) -> -0.26287838 | AD4: =SQRT(SUMSQ(AA4,AB4)) -> 274.65414 | AE4: =AE3 -> 75 | AF4: =(ASIN(AE4/AD4)) -> 0.27658361 | AG4: =DEGREES(AF4+ABS(AC4-Z4)) -> 16.086977 | AH4: =DEGREES(ATAN((Main!S4/2+Main!D4/2)/Main!C4)) -> 17.546956 | AI4: =A4 -> 2 | AJ4: =Main!S4*(G4-Main!T4)/G4/25 -> 1.7581644 | AK4: New/revised calculation
A5: 3 | B5: ='MDSL cloud import'!C5 -> 201.3326 | C5: ='MDSL cloud import'!D5 -> 136.87 | D5: ='MDSL cloud import'!E5 -> -70.5519 | E5: =SQRT((B5^2)+(C5^2)+(D5^2)) -> 253.46752 | F5: =SQRT((1)+((C5/B5)^2)+(D5/B5)^2) -> 1.2589492 | G5: =Main!C5 -> 75.776076 | H5: =E5+G5+Main!T5 -> 339.24359 | I5: =H5/F5*SIGN(B5) -> 269.46567 | J5: =I5*C5/B5 -> 183.18825 | K5: =I5*D5/B5 -> -94.427405 | L5: =(H5-Main!T5)/F5*SIGN(B5) -> 261.52254 | M5: =L5*C5/B5 -> 177.78835 | N5: =L5*D5/B5 -> -91.643936 | O5: =(H5)/2 -> 169.6218 | P5: =O5/F5*SIGN(B5) -> 134.73284 | Q5: =P5*C5/B5 -> 91.594124 | R5: =P5*D5/B5 -> -47.213703 | S5: =DEGREES(ATAN((ABS(C5))/(ABS(B5)))) -> 34.208663 | T5: =S5+180 -> 214.20866 | U5: =90-DEGREES(ACOS(ABS(D5/E5))) -> 16.161568 | V5: =-U5 -> -16.161568 | X5: =SQRT(SUMSQ(B5,C5)) -> 243.45064 | Y5: =(ATAN2(B5,C5)) -> 0.59705381 | Z5: =(ATAN2(X5,D5)) -> -0.28207257 | AA5: =-Main!D5/2*SIN(ABS(Z5))+X5 -> 243.13054 | AB5: =Main!D5/2*COS(ABS(Z5))*SIGN(Z5)+D5 -> -71.656453 | AC5: =ATAN2(AA5,AB5) -> -0.28660961 | AD5: =SQRT(SUMSQ(AA5,AB5)) -> 253.47013 | AE5: =AE4 -> 75 | AF5: =(ASIN(AE5/AD5)) -> 0.30039009 | AG5: =DEGREES(AF5+ABS(AC5-Z5)) -> 17.471038 | AH5: =DEGREES(ATAN((Main!S5/2+Main!D5/2)/Main!C5)) -> 19.039336 | AI5: =A5 -> 3 | AJ5: =Main!S5*(G5-Main!T5)/G5/25 -> 1.7360645
A6: 4 | B6: ='MDSL cloud import'!C6 -> 155.0181 | C6: ='MDSL cloud import'!D6 -> 158.4473 | D6: ='MDSL cloud import'!E6 -> -70.9056 | E6: =SQRT((B6^2)+(C6^2)+(D6^2)) -> 232.73109 | F6: =SQRT((1)+((C6/B6)^2)+(D6/B6)^2) -> 1.5013156 | G6: =Main!C6 -> 68.942582 | H6: =E6+G6+Main!T6 -> 311.67368 | I6: =H6/F6*SIGN(B6) -> 207.60037 | J6: =I6*C6/B6 -> 212.19276 | K6: =I6*D6/B6 -> -94.956839 | L6: =(H6-Main!T6)/F6*SIGN(B6) -> 200.93954 | M6: =L6*C6/B6 -> 205.38459 | N6: =L6*D6/B6 -> -91.910164 | O6: =(H6)/2 -> 155.83684 | P6: =O6/F6*SIGN(B6) -> 103.80018 | Q6: =P6*C6/B6 -> 106.09638 | R6: =P6*D6/B6 -> -47.478419 | S6: =DEGREES(ATAN((ABS(C6))/(ABS(B6)))) -> 45.62677 | T6: =S6+180 -> 225.62677 | U6: =90-DEGREES(ACOS(ABS(D6/E6))) -> 17.738161 | V6: =-U6 -> -17.738161 | X6: =SQRT(SUMSQ(B6,C6)) -> 221.66677 | Y6: =(ATAN2(B6,C6)) -> 0.79633737 | Z6: =(ATAN2(X6,D6)) -> -0.30958931 | AA6: =-Main!D6/2*SIN(ABS(Z6))+X6 -> 221.31641 | AB6: =Main!D6/2*COS(ABS(Z6))*SIGN(Z6)+D6 -> -72.000928 | AC6: =ATAN2(AA6,AB6) -> -0.31453059 | AD6: =SQRT(SUMSQ(AA6,AB6)) -> 232.73394 | AE6: =AE5 -> 75 | AF6: =(ASIN(AE6/AD6)) -> 0.32811208 | AG6: =DEGREES(AF6+ABS(AC6-Z6)) -> 19.082552 | AH6: =DEGREES(ATAN((Main!S6/2+Main!D6/2)/Main!C6)) -> 20.771794 | AI6: =A6 -> 4 | AJ6: =Main!S6*(G6-Main!T6)/G6/25 -> 1.7099035
A7: 5 | B7: ='MDSL cloud import'!C7 -> 106.2709 | C7: ='MDSL cloud import'!D7 -> 171.9591 | D7: ='MDSL cloud import'!E7 -> -71.3542 | E7: =SQRT((B7^2)+(C7^2)+(D7^2)) -> 214.37084 | F7: =SQRT((1)+((C7/B7)^2)+(D7/B7)^2) -> 2.0172111 | G7: =Main!C7 -> 62.832246 | H7: =E7+G7+Main!T7 -> 287.20309 | I7: =H7/F7*SIGN(B7) -> 142.37632 | J7: =I7*C7/B7 -> 230.38201 | K7: =I7*D7/B7 -> -95.596707 | L7: =(H7-Main!T7)/F7*SIGN(B7) -> 137.41898 | M7: =L7*C7/B7 -> 222.36043 | N7: =L7*D7/B7 -> -92.268167 | O7: =(H7)/2 -> 143.60154 | P7: =O7/F7*SIGN(B7) -> 71.188158 | Q7: =P7*C7/B7 -> 115.191 | R7: =P7*D7/B7 -> -47.798354 | S7: =DEGREES(ATAN((ABS(C7))/(ABS(B7)))) -> 58.283892 | T7: =S7+180 -> 238.28389 | U7: =90-DEGREES(ACOS(ABS(D7/E7))) -> 19.442096 | V7: =-U7 -> -19.442096 | X7: =SQRT(SUMSQ(B7,C7)) -> 202.14707 | Y7: =(ATAN2(B7,C7)) -> 1.0172458 | Z7: =(ATAN2(X7,D7)) -> -0.33932858 | AA7: =-Main!D7/2*SIN(ABS(Z7))+X7 -> 201.76428 | AB7: =Main!D7/2*COS(ABS(Z7))*SIGN(Z7)+D7 -> -72.438625 | AC7: =ATAN2(AA7,AB7) -> -0.34469307 | AD7: =SQRT(SUMSQ(AA7,AB7)) -> 214.37393 | AE7: =AE6 -> 75 | AF7: =(ASIN(AE7/AD7)) -> 0.35741736 | AG7: =DEGREES(AF7+ABS(AC7-Z7)) -> 20.785869 | AH7: =DEGREES(ATAN((Main!S7/2+Main!D7/2)/Main!C7)) -> 22.596472 | AI7: =A7 -> 5 | AJ7: =Main!S7*(G7-Main!T7)/G7/25 -> 1.6816921
A8: 6 | B8: ='MDSL cloud import'!C8 -> 56.74056 | C8: ='MDSL cloud import'!D8 -> 177.7703 | D8: ='MDSL cloud import'!E8 -> -71.7895 | E8: =SQRT((B8^2)+(C8^2)+(D8^2)) -> 199.93875 | F8: =SQRT((1)+((C8/B8)^2)+(D8/B8)^2) -> 3.5237359 | G8: =Main!C8 -> 57.97763 | H8: =E8+G8+Main!T8 -> 267.91638 | I8: =H8/F8*SIGN(B8) -> 76.031912 | J8: =I8*C8/B8 -> 238.21083 | K8: =I8*D8/B8 -> -96.197376 | L8: =(H8-Main!T8)/F8*SIGN(B8) -> 73.194015 | M8: =L8*C8/B8 -> 229.31959 | N8: =L8*D8/B8 -> -92.606801 | O8: =(H8)/2 -> 133.95819 | P8: =O8/F8*SIGN(B8) -> 38.015956 | Q8: =P8*C8/B8 -> 119.10541 | R8: =P8*D8/B8 -> -48.098688 | S8: =DEGREES(ATAN((ABS(C8))/(ABS(B8)))) -> 72.298005 | T8: =S8+180 -> 252.29801 | U8: =90-DEGREES(ACOS(ABS(D8/E8))) -> 21.042323 | V8: =-U8 -> -21.042323 | X8: =SQRT(SUMSQ(B8,C8)) -> 186.60592 | Y8: =(ATAN2(B8,C8)) -> 1.2618382 | Z8: =(ATAN2(X8,D8)) -> -0.36725782 | AA8: =-Main!D8/2*SIN(ABS(Z8))+X8 -> 186.19301 | AB8: =Main!D8/2*COS(ABS(Z8))*SIGN(Z8)+D8 -> -72.862813 | AC8: =ATAN2(AA8,AB8) -> -0.37300952 | AD8: =SQRT(SUMSQ(AA8,AB8)) -> 199.94206 | AE8: =AE7 -> 75 | AF8: =(ASIN(AE8/AD8)) -> 0.38451401 | AG8: =DEGREES(AF8+ABS(AC8-Z8)) -> 22.360578 | AH8: =DEGREES(ATAN((Main!S8/2+Main!D8/2)/Main!C8)) -> 24.27709 | AI8: =A8 -> 6 | AJ8: =Main!S8*(G8-Main!T8)/G8/25 -> 1.6550394
A9: 7 | B9: ='MDSL cloud import'!C9 -> 7.351419 | C9: ='MDSL cloud import'!D9 -> 176.2461 | D9: ='MDSL cloud import'!E9 -> -72.1241 | E9: =SQRT((B9^2)+(C9^2)+(D9^2)) -> 190.57444 | F9: =SQRT((1)+((C9/B9)^2)+(D9/B9)^2) -> 25.92349 | G9: =Main!C9 -> 54.797151 | H9: =E9+G9+Main!T9 -> 255.37159 | I9: =H9/F9*SIGN(B9) -> 9.8509725 | J9: =I9*C9/B9 -> 236.17148 | K9: =I9*D9/B9 -> -96.646991 | L9: =(H9-Main!T9)/F9*SIGN(B9) -> 9.465222 | M9: =L9*C9/B9 -> 226.92333 | N9: =L9*D9/B9 -> -92.862428 | O9: =(H9)/2 -> 127.6858 | P9: =O9/F9*SIGN(B9) -> 4.9254863 | Q9: =P9*C9/B9 -> 118.08574 | R9: =P9*D9/B9 -> -48.323496 | S9: =DEGREES(ATAN((ABS(C9))/(ABS(B9)))) -> 87.611514 | T9: =S9+180 -> 267.61151 | U9: =90-DEGREES(ACOS(ABS(D9/E9))) -> 22.238096 | V9: =-U9 -> -22.238096 | X9: =SQRT(SUMSQ(B9,C9)) -> 176.39935 | Y9: =(ATAN2(B9,C9)) -> 1.5291094 | Z9: =(ATAN2(X9,D9)) -> -0.38812799 | AA9: =-Main!D9/2*SIN(ABS(Z9))+X9 -> 175.96413 | AB9: =Main!D9/2*COS(ABS(Z9))*SIGN(Z9)+D9 -> -73.188562 | AC9: =ATAN2(AA9,AB9) -> -0.39416231 | AD9: =SQRT(SUMSQ(AA9,AB9)) -> 190.57791 | AE9: =AE8 -> 75 | AF9: =(ASIN(AE9/AD9)) -> 0.40447899 | AG9: =DEGREES(AF9+ABS(AC9-Z9)) -> 23.520679 | AH9: =DEGREES(ATAN((Main!S9/2+Main!D9/2)/Main!C9)) -> 25.511157 | AI9: =A9 -> 7 | AJ9: =Main!S9*(G9-Main!T9)/G9/25 -> 1.6350175
A10: 8 | B10: ='MDSL cloud import'!C10 -> -41.7583 | C10: ='MDSL cloud import'!D10 -> 167.3279 | D10: ='MDSL cloud import'!E10 -> -72.2656 | E10: =SQRT((B10^2)+(C10^2)+(D10^2)) -> 186.9885 | F10: =SQRT((1)+((C10/B10)^2)+(D10/B10)^2) -> 4.4778762 | G10: =Main!C10 -> 53.571762 | H10: =E10+G10+Main!T10 -> 250.56026 | I10: =H10/F10*SIGN(B10) -> -55.955156 | J10: =I10*C10/B10 -> 224.21551 | K10: =I10*D10/B10 -> -96.834232 | L10: =(H10-Main!T10)/F10*SIGN(B10) -> -53.721954 | M10: =L10*C10/B10 -> 215.26695 | N10: =L10*D10/B10 -> -92.969523 | O10: =(H10)/2 -> 125.28013 | P10: =O10/F10*SIGN(B10) -> -27.977578 | Q10: =P10*C10/B10 -> 112.10776 | R10: =P10*D10/B10 -> -48.417116 | S10: =DEGREES(ATAN((ABS(C10))/(ABS(B10)))) -> 75.987503 | T10: =-S10 -> -75.987503 | U10: =90-DEGREES(ACOS(ABS(D10/E10))) -> 22.735081 | V10: =-U10 -> -22.735081 | X10: =SQRT(SUMSQ(B10,C10)) -> 172.4598 | Y10: =(ATAN2(B10,C10)) -> 1.8153605 | Z10: =(ATAN2(X10,D10)) -> -0.39680203 | AA10: =-Main!D10/2*SIN(ABS(Z10))+X10 -> 172.01536 | AB10: =Main!D10/2*COS(ABS(Z10))*SIGN(Z10)+D10 -> -73.326247 | AC10: =ATAN2(AA10,AB10) -> -0.40295206 | AD10: =SQRT(SUMSQ(AA10,AB10)) -> 186.99204 | AE10: =AE9 -> 75 | AF10: =(ASIN(AE10/AD10)) -> 0.41270273 | AG10: =DEGREES(AF10+ABS(AC10-Z10)) -> 23.998496 | AH10: =DEGREES(ATAN((Main!S10/2+Main!D10/2)/Main!C10)) -> 26.018405 | AI10: =A10 -> 8 | AJ10: =Main!S10*(G10-Main!T10)/G10/25 -> 1.626669
A11: 9 | B11: ='MDSL cloud import'!C11 -> -89.0623 | C11: ='MDSL cloud import'!D11 -> 150.8126 | D11: ='MDSL cloud import'!E11 -> -72.1683 | E11: =SQRT((B11^2)+(C11^2)+(D11^2)) -> 189.43283 | F11: =SQRT((1)+((C11/B11)^2)+(D11/B11)^2) -> 2.1269699 | G11: =Main!C11 -> 54.407518 | H11: =E11+G11+Main!T11 -> 253.84035 | I11: =H11/F11*SIGN(B11) -> -119.34365 | J11: =I11*C11/B11 -> 202.08917 | K11: =I11*D11/B11 -> -96.705658 | L11: =(H11-Main!T11)/F11*SIGN(B11) -> -114.64213 | M11: =L11*C11/B11 -> 194.1279 | N11: =L11*D11/B11 -> -92.895954 | O11: =(H11)/2 -> 126.92017 | P11: =O11/F11*SIGN(B11) -> -59.671825 | Q11: =P11*C11/B11 -> 101.04458 | R11: =P11*D11/B11 -> -48.352829 | S11: =DEGREES(ATAN((ABS(C11))/(ABS(B11)))) -> 59.436048 | T11: =-S11 -> -59.436048 | U11: =90-DEGREES(ACOS(ABS(D11/E11))) -> 22.393804 | V11: =-U11 -> -22.393804 | X11: =SQRT(SUMSQ(B11,C11)) -> 175.14718 | Y11: =(ATAN2(B11,C11)) -> 2.1042379 | Z11: =(ATAN2(X11,D11)) -> -0.39084561 | AA11: =-Main!D11/2*SIN(ABS(Z11))+X11 -> 174.70906 | AB11: =Main!D11/2*COS(ABS(Z11))*SIGN(Z11)+D11 -> -73.231575 | AC11: =ATAN2(AA11,AB11) -> -0.39691629 | AD11: =SQRT(SUMSQ(AA11,AB11)) -> 189.43632 | AE11: =AE10 -> 75 | AF11: =(ASIN(AE11/AD11)) -> 0.40706014 | AG11: =DEGREES(AF11+ABS(AC11-Z11)) -> 23.670652 | AH11: =DEGREES(ATAN((Main!S11/2+Main!D11/2)/Main!C11)) -> 25.670434 | AI11: =A11 -> 9 | AJ11: =Main!S11*(G11-Main!T11)/G11/25 -> 1.6324037
A12: 10 | B12: ='MDSL cloud import'!C12 -> -132.361 | C12: ='MDSL cloud import'!D12 -> 126.955 | D12: ='MDSL cloud import'!E12 -> -71.8898 | E12: =SQRT((B12^2)+(C12^2)+(D12^2)) -> 196.99023 | F12: =SQRT((1)+((C12/B12)^2)+(D12/B12)^2) -> 1.48828 | G12: =Main!C12 -> 56.97906 | H12: =E12+G12+Main!T12 -> 263.96929 | I12: =H12/F12*SIGN(B12) -> -177.36534 | J12: =I12*C12/B12 -> 170.12124 | K12: =I12*D12/B12 -> -96.333201 | L12: =(H12-Main!T12)/F12*SIGN(B12) -> -170.64617 | M12: =L12*C12/B12 -> 163.6765 | N12: =L12*D12/B12 -> -92.683792 | O12: =(H12)/2 -> 131.98464 | P12: =O12/F12*SIGN(B12) -> -88.68267 | Q12: =P12*C12/B12 -> 85.060618 | R12: =P12*D12/B12 -> -48.166601 | S12: =DEGREES(ATAN((ABS(C12))/(ABS(B12)))) -> 43.805719 | T12: =-S12 -> -43.805719 | U12: =90-DEGREES(ACOS(ABS(D12/E12))) -> 21.403948 | V12: =-U12 -> -21.403948 | X12: =SQRT(SUMSQ(B12,C12)) -> 183.40394 | Y12: =(ATAN2(B12,C12)) -> 2.3770386 | Z12: =(ATAN2(X12,D12)) -> -0.37356937 | AA12: =-Main!D12/2*SIN(ABS(Z12))+X12 -> 182.98426 | AB12: =Main!D12/2*COS(ABS(Z12))*SIGN(Z12)+D12 -> -72.960485 | AC12: =ATAN2(AA12,AB12) -> -0.37940716 | AD12: =SQRT(SUMSQ(AA12,AB12)) -> 196.99358 | AE12: =AE11 -> 75 | AF12: =(ASIN(AE12/AD12)) -> 0.39057812 | AG12: =DEGREES(AF12+ABS(AC12-Z12)) -> 22.712958 | AH12: =DEGREES(ATAN((Main!S12/2+Main!D12/2)/Main!C12)) -> 24.652309 | AI12: =A12 -> 10 | AJ12: =Main!S12*(G12-Main!T12)/G12/25 -> 1.6489939
A13: 11 | B13: ='MDSL cloud import'!C13 -> -170.499 | C13: ='MDSL cloud import'!D13 -> 95.57272 | D13: ='MDSL cloud import'!E13 -> -71.5318 | E13: =SQRT((B13^2)+(C13^2)+(D13^2)) -> 208.13662 | F13: =SQRT((1)+((C13/B13)^2)+(D13/B13)^2) -> 1.2207498 | G13: =Main!C13 -> 60.741525 | H13: =E13+G13+Main!T13 -> 278.87814 | I13: =H13/F13*SIGN(B13) -> -228.44824 | J13: =I13*C13/B13 -> 128.056 | K13: =I13*D13/B13 -> -95.844046 | L13: =(H13-Main!T13)/F13*SIGN(B13) -> -220.25655 | M13: =L13*C13/B13 -> 123.46417 | N13: =L13*D13/B13 -> -92.407274 | O13: =(H13)/2 -> 139.43907 | P13: =O13/F13*SIGN(B13) -> -114.22412 | Q13: =P13*C13/B13 -> 64.028 | R13: =P13*D13/B13 -> -47.922023 | S13: =DEGREES(ATAN((ABS(C13))/(ABS(B13)))) -> 29.272684 | T13: =-S13 -> -29.272684 | U13: =90-DEGREES(ACOS(ABS(D13/E13))) -> 20.101065 | V13: =-U13 -> -20.101065 | X13: =SQRT(SUMSQ(B13,C13)) -> 195.45857 | Y13: =(ATAN2(B13,C13)) -> 2.6306879 | Z13: =(ATAN2(X13,D13)) -> -0.35082977 | AA13: =-Main!D13/2*SIN(ABS(Z13))+X13 -> 195.06334 | AB13: =Main!D13/2*COS(ABS(Z13))*SIGN(Z13)+D13 -> -72.611751 | AC13: =ATAN2(AA13,AB13) -> -0.35635493 | AD13: =SQRT(SUMSQ(AA13,AB13)) -> 208.1398 | AE13: =AE12 -> 75 | AF13: =(ASIN(AE13/AD13)) -> 0.36862672 | AG13: =DEGREES(AF13+ABS(AC13-Z13)) -> 21.437324 | AH13: =DEGREES(ATAN((Main!S13/2+Main!D13/2)/Main!C13)) -> 23.292494 | AI13: =A13 -> 11 | AJ13: =Main!S13*(G13-Main!T13)/G13/25 -> 1.670736
A14: 12 | B14: ='MDSL cloud import'!C14 -> -201.258 | C14: ='MDSL cloud import'!D14 -> 56.97774 | D14: ='MDSL cloud import'!E14 -> -71.1818 | E14: =SQRT((B14^2)+(C14^2)+(D14^2)) -> 220.94817 | F14: =SQRT((1)+((C14/B14)^2)+(D14/B14)^2) -> 1.0978355 | G14: =Main!C14 -> 65.028733 | H14: =E14+G14+Main!T14 -> 295.9769 | I14: =H14/F14*SIGN(B14) -> -269.60042 | J14: =I14*C14/B14 -> 76.326023 | K14: =I14*D14/B14 -> -95.353443 | L14: =(H14-Main!T14)/F14*SIGN(B14) -> -260.49159 | M14: =L14*C14/B14 -> 73.74724 | N14: =L14*D14/B14 -> -92.131791 | O14: =(H14)/2 -> 147.98845 | P14: =O14/F14*SIGN(B14) -> -134.80021 | Q14: =P14*C14/B14 -> 38.163011 | R14: =P14*D14/B14 -> -47.676721 | S14: =DEGREES(ATAN((ABS(C14))/(ABS(B14)))) -> 15.807239 | T14: =-S14 -> -15.807239 | U14: =90-DEGREES(ACOS(ABS(D14/E14))) -> 18.793914 | V14: =-U14 -> -18.793914 | X14: =SQRT(SUMSQ(B14,C14)) -> 209.16798 | Y14: =(ATAN2(B14,C14)) -> 2.8657043 | Z14: =(ATAN2(X14,D14)) -> -0.32801569 | AA14: =-Main!D14/2*SIN(ABS(Z14))+X14 -> 208.79749 | AB14: =Main!D14/2*COS(ABS(Z14))*SIGN(Z14)+D14 -> -72.270486 | AC14: =ATAN2(AA14,AB14) -> -0.33322048 | AD14: =SQRT(SUMSQ(AA14,AB14)) -> 220.95116 | AE14: =AE13 -> 75 | AF14: =(ASIN(AE14/AD14)) -> 0.34632311 | AG14: =DEGREES(AF14+ABS(AC14-Z14)) -> 20.141065 | AH14: =DEGREES(ATAN((Main!S14/2+Main!D14/2)/Main!C14)) -> 21.906536 | AI14: =A14 -> 12 | AJ14: =Main!S14*(G14-Main!T14)/G14/25 -> 1.6924436
A15: 13 | B15: ='MDSL cloud import'!C15 -> -221.948 | C15: ='MDSL cloud import'!D15 -> 12.56229 | D15: ='MDSL cloud import'!E15 -> -70.8925 | E15: =SQRT((B15^2)+(C15^2)+(D15^2)) -> 233.33339 | F15: =SQRT((1)+((C15/B15)^2)+(D15/B15)^2) -> 1.0512976 | G15: =Main!C15 -> 69.141984 | H15: =E15+G15+Main!T15 -> 312.47538 | I15: =H15/F15*SIGN(B15) -> -297.22829 | J15: =I15*C15/B15 -> 16.823166 | K15: =I15*D15/B15 -> -94.937807 | L15: =(H15-Main!T15)/F15*SIGN(B15) -> -287.71623 | M15: =L15*C15/B15 -> 16.284782 | N15: =L15*D15/B15 -> -91.899558 | O15: =(H15)/2 -> 156.23769 | P15: =O15/F15*SIGN(B15) -> -148.61414 | Q15: =P15*C15/B15 -> 8.4115828 | R15: =P15*D15/B15 -> -47.468904 | S15: =DEGREES(ATAN((ABS(C15))/(ABS(B15)))) -> 3.2394933 | T15: =-S15 -> -3.2394933 | U15: =90-DEGREES(ACOS(ABS(D15/E15))) -> 17.687482 | V15: =-U15 -> -17.687482 | X15: =SQRT(SUMSQ(B15,C15)) -> 222.30323 | Y15: =(ATAN2(B15,C15)) -> 3.0850528 | Z15: =(ATAN2(X15,D15)) -> -0.3087048 | AA15: =-Main!D15/2*SIN(ABS(Z15))+X15 -> 221.95383 | AB15: =Main!D15/2*COS(ABS(Z15))*SIGN(Z15)+D15 -> -71.988137 | AC15: =ATAN2(AA15,AB15) -> -0.31363333 | AD15: =SQRT(SUMSQ(AA15,AB15)) -> 233.33623 | AE15: =AE14 -> 75 | AF15: =(ASIN(AE15/AD15)) -> 0.32723352 | AG15: =DEGREES(AF15+ABS(AC15-Z15)) -> 19.031484 | AH15: =DEGREES(ATAN((Main!S15/2+Main!D15/2)/Main!C15)) -> 20.716982 | AI15: =A15 -> 13 | AJ15: =Main!S15*(G15-Main!T15)/G15/25 -> 1.7107401
A16: 14 | B16: ='MDSL cloud import'!C16 -> -230.423 | C16: ='MDSL cloud import'!D16 -> -35.1111 | D16: ='MDSL cloud import'!E16 -> -70.7108 | E16: =SQRT((B16^2)+(C16^2)+(D16^2)) -> 243.57251 | F16: =SQRT((1)+((C16/B16)^2)+(D16/B16)^2) -> 1.0570668 | G16: =Main!C16 -> 72.523027 | H16: =E16+G16+Main!T16 -> 326.09553 | I16: =H16/F16*SIGN(B16) -> -308.49094 | J16: =I16*C16/B16 -> -47.006836 | K16: =I16*D16/B16 -> -94.667811 | L16: =(H16-Main!T16)/F16*SIGN(B16) -> -299.0308 | M16: =L16*C16/B16 -> -45.565331 | N16: =L16*D16/B16 -> -91.764741 | O16: =(H16)/2 -> 163.04777 | P16: =O16/F16*SIGN(B16) -> -154.24547 | Q16: =P16*C16/B16 -> -23.503418 | R16: =P16*D16/B16 -> -47.333906 | S16: =DEGREES(ATAN((ABS(C16))/(ABS(B16)))) -> 8.6638982 | T16: =S16 -> 8.6638982 | U16: =90-DEGREES(ACOS(ABS(D16/E16))) -> 16.876336 | V16: =-U16 -> -16.876336 | X16: =SQRT(SUMSQ(B16,C16)) -> 233.08271 | Y16: =(ATAN2(B16,C16)) -> -2.9903791 | Z16: =(ATAN2(X16,D16)) -> -0.29454762 | AA16: =-Main!D16/2*SIN(ABS(Z16))+X16 -> 232.74885 | AB16: =Main!D16/2*COS(ABS(Z16))*SIGN(Z16)+D16 -> -71.811274 | AC16: =ATAN2(AA16,AB16) -> -0.29926898 | AD16: =SQRT(SUMSQ(AA16,AB16)) -> 243.57522 | AE16: =AE15 -> 75 | AF16: =(ASIN(AE16/AD16)) -> 0.31299878 | AG16: =DEGREES(AF16+ABS(AC16-Z16)) -> 18.204022 | AH16: =DEGREES(ATAN((Main!S16/2+Main!D16/2)/Main!C16)) -> 19.828043 | AI16: =A16 -> 14 | AJ16: =Main!S16*(G16-Main!T16)/G16/25 -> 1.7242255
A17: 15 | B17: ='MDSL cloud import'!C17 -> -225.927 | C17: ='MDSL cloud import'!D17 -> -82.9365 | D17: ='MDSL cloud import'!E17 -> -70.5931 | E17: =SQRT((B17^2)+(C17^2)+(D17^2)) -> 250.80841 | F17: =SQRT((1)+((C17/B17)^2)+(D17/B17)^2) -> 1.1101303 | G17: =Main!C17 -> 74.903158 | H17: =E17+G17+Main!T17 -> 335.71157 | I17: =H17/F17*SIGN(B17) -> -302.40735 | J17: =I17*C17/B17 -> -111.012 | K17: =I17*D17/B17 -> -94.490134 | L17: =(H17-Main!T17)/F17*SIGN(B17) -> -293.3994 | M17: =L17*C17/B17 -> -107.70523 | N17: =L17*D17/B17 -> -91.675512 | O17: =(H17)/2 -> 167.85578 | P17: =O17/F17*SIGN(B17) -> -151.20368 | Q17: =P17*C17/B17 -> -55.505999 | R17: =P17*D17/B17 -> -47.245067 | S17: =DEGREES(ATAN((ABS(C17))/(ABS(B17)))) -> 20.157895 | T17: =S17 -> 20.157895 | U17: =90-DEGREES(ACOS(ABS(D17/E17))) -> 16.347496 | V17: =-U17 -> -16.347496 | X17: =SQRT(SUMSQ(B17,C17)) -> 240.6688 | Y17: =(ATAN2(B17,C17)) -> -2.789771 | Z17: =(ATAN2(X17,D17)) -> -0.28531763 | AA17: =-Main!D17/2*SIN(ABS(Z17))+X17 -> 240.34512 | AB17: =Main!D17/2*COS(ABS(Z17))*SIGN(Z17)+D17 -> -71.696608 | AC17: =ATAN2(AA17,AB17) -> -0.28990277 | AD17: =SQRT(SUMSQ(AA17,AB17)) -> 250.81105 | AE17: =AE16 -> 75 | AF17: =(ASIN(AE17/AD17)) -> 0.30367587 | AG17: =DEGREES(AF17+ABS(AC17-Z17)) -> 17.662055 | AH17: =DEGREES(ATAN((Main!S17/2+Main!D17/2)/Main!C17)) -> 19.244986 | AI17: =A17 -> 15 | AJ17: =Main!S17*(G17-Main!T17)/G17/25 -> 1.7329886
A18: 16 | B18: ='MDSL cloud import'!C18 -> -209.229 | C18: ='MDSL cloud import'!D18 -> -127.899 | D18: ='MDSL cloud import'!E18 -> -70.5263 | E18: =SQRT((B18^2)+(C18^2)+(D18^2)) -> 255.16443 | F18: =SQRT((1)+((C18/B18)^2)+(D18/B18)^2) -> 1.2195462 | G18: =Main!C18 -> 76.332661 | H18: =E18+G18+Main!T18 -> 341.49709 | I18: =H18/F18*SIGN(B18) -> -280.01981 | J18: =I18*C18/B18 -> -171.17251 | K18: =I18*D18/B18 -> -94.388259 | L18: =(H18-Main!T18)/F18*SIGN(B18) -> -271.82004 | M18: =L18*C18/B18 -> -166.1601 | N18: =L18*D18/B18 -> -91.624304 | O18: =(H18)/2 -> 170.74855 | P18: =O18/F18*SIGN(B18) -> -140.0099 | Q18: =P18*C18/B18 -> -85.586256 | R18: =P18*D18/B18 -> -47.194129 | S18: =DEGREES(ATAN((ABS(C18))/(ABS(B18)))) -> 31.436909 | T18: =S18 -> 31.436909 | U18: =90-DEGREES(ACOS(ABS(D18/E18))) -> 16.045194 | V18: =-U18 -> -16.045194 | X18: =SQRT(SUMSQ(B18,C18)) -> 245.22424 | Y18: =(ATAN2(B18,C18)) -> -2.5929151 | Z18: =(ATAN2(X18,D18)) -> -0.28004146 | AA18: =-Main!D18/2*SIN(ABS(Z18))+X18 -> 244.90639 | AB18: =Main!D18/2*COS(ABS(Z18))*SIGN(Z18)+D18 -> -71.631501 | AC18: =ATAN2(AA18,AB18) -> -0.28454833 | AD18: =SQRT(SUMSQ(AA18,AB18)) -> 255.16702 | AE18: =AE17 -> 75 | AF18: =(ASIN(AE18/AD18)) -> 0.29833078 | AG18: =DEGREES(AF18+ABS(AC18-Z18)) -> 17.351319 | AH18: =DEGREES(ATAN((Main!S18/2+Main!D18/2)/Main!C18)) -> 18.910405 | AI18: =A18 -> 16 | AJ18: =Main!S18*(G18-Main!T18)/G18/25 -> 1.737989
A19: 17 | B19: ='MDSL cloud import'!C19 -> -182.273 | C19: ='MDSL cloud import'!D19 -> -167.656 | D19: ='MDSL cloud import'!E19 -> -70.4918 | E19: =SQRT((B19^2)+(C19^2)+(D19^2)) -> 257.48995 | F19: =SQRT((1)+((C19/B19)^2)+(D19/B19)^2) -> 1.412661 | G19: =Main!C19 -> 77.094853 | H19: =E19+G19+Main!T19 -> 344.5848 | I19: =H19/F19*SIGN(B19) -> -243.92605 | J19: =I19*C19/B19 -> -224.36491 | K19: =I19*D19/B19 -> -94.335344 | L19: =(H19-Main!T19)/F19*SIGN(B19) -> -236.84721 | M19: =L19*C19/B19 -> -217.85374 | N19: =L19*D19/B19 -> -91.597692 | O19: =(H19)/2 -> 172.2924 | P19: =O19/F19*SIGN(B19) -> -121.96302 | Q19: =P19*C19/B19 -> -112.18246 | R19: =P19*D19/B19 -> -47.167672 | S19: =DEGREES(ATAN((ABS(C19))/(ABS(B19)))) -> 42.60807 | T19: =S19 -> 42.60807 | U19: =90-DEGREES(ACOS(ABS(D19/E19))) -> 15.888444 | V19: =-U19 -> -15.888444 | X19: =SQRT(SUMSQ(B19,C19)) -> 247.65294 | Y19: =(ATAN2(B19,C19)) -> -2.3979416 | Z19: =(ATAN2(X19,D19)) -> -0.27730567 | AA19: =-Main!D19/2*SIN(ABS(Z19))+X19 -> 247.33811 | AB19: =Main!D19/2*COS(ABS(Z19))*SIGN(Z19)+D19 -> -71.597866 | AC19: =ATAN2(AA19,AB19) -> -0.28177183 | AD19: =SQRT(SUMSQ(AA19,AB19)) -> 257.49252 | AE19: =AE18 -> 75 | AF19: =(ASIN(AE19/AD19)) -> 0.29555476 | AG19: =DEGREES(AF19+ABS(AC19-Z19)) -> 17.189933 | AH19: =DEGREES(ATAN((Main!S19/2+Main!D19/2)/Main!C19)) -> 18.736554 | AI19: =A19 -> 17 | AJ19: =Main!S19*(G19-Main!T19)/G19/25 -> 1.7405793
A20: 18 | B20: ='MDSL cloud import'!C20 -> -147.473 | C20: ='MDSL cloud import'!D20 -> -200.839 | D20: ='MDSL cloud import'!E20 -> -70.4707 | E20: =SQRT((B20^2)+(C20^2)+(D20^2)) -> 258.94152 | F20: =SQRT((1)+((C20/B20)^2)+(D20/B20)^2) -> 1.7558571 | G20: =Main!C20 -> 77.570277 | H20: =E20+G20+Main!T20 -> 346.51179 | I20: =H20/F20*SIGN(B20) -> -197.34624 | J20: =I20*C20/B20 -> -268.75985 | K20: =I20*D20/B20 -> -94.302872 | L20: =(H20-Main!T20)/F20*SIGN(B20) -> -191.65101 | M20: =L20*C20/B20 -> -261.00369 | N20: =L20*D20/B20 -> -91.581381 | O20: =(H20)/2 -> 173.2559 | P20: =O20/F20*SIGN(B20) -> -98.673118 | Q20: =P20*C20/B20 -> -134.37992 | R20: =P20*D20/B20 -> -47.151436 | S20: =DEGREES(ATAN((ABS(C20))/(ABS(B20)))) -> 53.710732 | T20: =S20 -> 53.710732 | U20: =90-DEGREES(ACOS(ABS(D20/E20))) -> 15.792191 | V20: =-U20 -> -15.792191 | X20: =SQRT(SUMSQ(B20,C20)) -> 249.16779 | Y20: =(ATAN2(B20,C20)) -> -2.2041635 | Z20: =(ATAN2(X20,D20)) -> -0.27562572 | AA20: =-Main!D20/2*SIN(ABS(Z20))+X20 -> 248.85482 | AB20: =Main!D20/2*COS(ABS(Z20))*SIGN(Z20)+D20 -> -71.577293 | AC20: =ATAN2(AA20,AB20) -> -0.28006685 | AD20: =SQRT(SUMSQ(AA20,AB20)) -> 258.94407 | AE20: =AE19 -> 75 | AF20: =(ASIN(AE20/AD20)) -> 0.29384843 | AG20: =DEGREES(AF20+ABS(AC20-Z20)) -> 17.090733 | AH20: =DEGREES(ATAN((Main!S20/2+Main!D20/2)/Main!C20)) -> 18.629664 | AI20: =A20 -> 18 | AJ20: =Main!S20*(G20-Main!T20)/G20/25 -> 1.7421693
A21: 19 | B21: ='MDSL cloud import'!C21 -> -107.125 | C21: ='MDSL cloud import'!D21 -> -226.898 | D21: ='MDSL cloud import'!E21 -> -70.4467 | E21: =SQRT((B21^2)+(C21^2)+(D21^2)) -> 260.61697 | F21: =SQRT((1)+((C21/B21)^2)+(D21/B21)^2) -> 2.4328305 | G21: =Main!C21 -> 78.118722 | H21: =E21+G21+Main!T21 -> 348.73569 | I21: =H21/F21*SIGN(B21) -> -143.34566 | J21: =I21*C21/B21 -> -303.6158 | K21: =I21*D21/B21 -> -94.265844 | L21: =(H21-Main!T21)/F21*SIGN(B21) -> -139.23522 | M21: =L21*C21/B21 -> -294.90962 | N21: =L21*D21/B21 -> -91.56277 | O21: =(H21)/2 -> 174.36785 | P21: =O21/F21*SIGN(B21) -> -71.672829 | Q21: =P21*C21/B21 -> -151.8079 | R21: =P21*D21/B21 -> -47.132922 | S21: =DEGREES(ATAN((ABS(C21))/(ABS(B21)))) -> 64.726671 | T21: =S21 -> 64.726671 | U21: =90-DEGREES(ACOS(ABS(D21/E21))) -> 15.682561 | V21: =-U21 -> -15.682561 | X21: =SQRT(SUMSQ(B21,C21)) -> 250.91526 | Y21: =(ATAN2(B21,C21)) -> -2.0118991 | Z21: =(ATAN2(X21,D21)) -> -0.27371232 | AA21: =-Main!D21/2*SIN(ABS(Z21))+X21 -> 250.60441 | AB21: =Main!D21/2*COS(ABS(Z21))*SIGN(Z21)+D21 -> -71.55389 | AC21: =ATAN2(AA21,AB21) -> -0.2781249 | AD21: =SQRT(SUMSQ(AA21,AB21)) -> 260.61951 | AE21: =AE20 -> 75 | AF21: =(ASIN(AE21/AD21)) -> 0.29190363 | AG21: =DEGREES(AF21+ABS(AC21-Z21)) -> 16.977668 | AH21: =DEGREES(ATAN((Main!S21/2+Main!D21/2)/Main!C21)) -> 18.50781 | AI21: =A21 -> 19 | AJ21: =Main!S21*(G21-Main!T21)/G21/25 -> 1.7439794
A22: 20 | B22: ='MDSL cloud import'!C22 -> -63.1068 | C22: ='MDSL cloud import'!D22 -> -245.785 | D22: ='MDSL cloud import'!E22 -> -70.4085 | E22: =SQRT((B22^2)+(C22^2)+(D22^2)) -> 263.34405 | F22: =SQRT((1)+((C22/B22)^2)+(D22/B22)^2) -> 4.1729902 | G22: =Main!C22 -> 79.010721 | H22: =E22+G22+Main!T22 -> 352.35478 | I22: =H22/F22*SIGN(B22) -> -84.437001 | J22: =I22*C22/B22 -> -328.86073 | K22: =I22*D22/B22 -> -94.206688 | L22: =(H22-Main!T22)/F22*SIGN(B22) -> -82.040638 | M22: =L22*C22/B22 -> -319.5275 | N22: =L22*D22/B22 -> -91.533056 | O22: =(H22)/2 -> 176.17739 | P22: =O22/F22*SIGN(B22) -> -42.218501 | Q22: =P22*C22/B22 -> -164.43037 | R22: =P22*D22/B22 -> -47.103344 | S22: =DEGREES(ATAN((ABS(C22))/(ABS(B22)))) -> 75.600014 | T22: =S22 -> 75.600014 | U22: =90-DEGREES(ACOS(ABS(D22/E22))) -> 15.50742 | V22: =-U22 -> -15.50742 | X22: =SQRT(SUMSQ(B22,C22)) -> 253.75724 | Y22: =(ATAN2(B22,C22)) -> -1.8221235 | Z22: =(ATAN2(X22,D22)) -> -0.27065554 | AA22: =-Main!D22/2*SIN(ABS(Z22))+X22 -> 253.44977 | AB22: =Main!D22/2*COS(ABS(Z22))*SIGN(Z22)+D22 -> -71.516635 | AC22: =ATAN2(AA22,AB22) -> -0.27502242 | AD22: =SQRT(SUMSQ(AA22,AB22)) -> 263.34657 | AE22: =AE21 -> 75 | AF22: =(ASIN(AE22/AD22)) -> 0.28879342 | AG22: =DEGREES(AF22+ABS(AC22-Z22)) -> 16.796848 | AH22: =DEGREES(ATAN((Main!S22/2+Main!D22/2)/Main!C22)) -> 18.312878 | AI22: =A22 -> 20 | AJ22: =Main!S22*(G22-Main!T22)/G22/25 -> 1.7468698
A23: 21 | B23: ='MDSL cloud import'!C23 -> 277.002 | C23: ='MDSL cloud import'!D23 -> 70.37124 | D23: ='MDSL cloud import'!E23 -> -23.4255 | E23: =SQRT((B23^2)+(C23^2)+(D23^2)) -> 286.75943 | F23: =SQRT((1)+((C23/B23)^2)+(D23/B23)^2) -> 1.0352251 | G23: =Main!C23 -> 86.638244 | H23: =E23+G23+Main!T23 -> 383.39768 | I23: =H23/F23*SIGN(B23) -> 370.35198 | J23: =I23*C23/B23 -> 94.086425 | K23: =I23*D23/B23 -> -31.319919 | L23: =(H23-Main!T23)/F23*SIGN(B23) -> 360.69224 | M23: =L23*C23/B23 -> 91.632408 | N23: =L23*D23/B23 -> -30.503015 | O23: =(H23)/2 -> 191.69884 | P23: =O23/F23*SIGN(B23) -> 185.17599 | Q23: =P23*C23/B23 -> 47.043213 | R23: =P23*D23/B23 -> -15.65996 | S23: =DEGREES(ATAN((ABS(C23))/(ABS(B23)))) -> 14.254215 | T23: =S23+180 -> 194.25422 | U23: =90-DEGREES(ACOS(ABS(D23/E23))) -> 4.685738 | V23: =-U23 -> -4.685738 | X23: =SQRT(SUMSQ(B23,C23)) -> 285.80101 | Y23: =(ATAN2(B23,C23)) -> 0.24878299 | Z23: =(ATAN2(X23,D23)) -> -0.081781556 | AA23: =-Main!D23/2*SIN(ABS(Z23))+X23 -> 285.70707 | AB23: =Main!D23/2*COS(ABS(Z23))*SIGN(Z23)+D23 -> -24.571656 | AC23: =ATAN2(AA23,AB23) -> -0.085791865 | AD23: =SQRT(SUMSQ(AA23,AB23)) -> 286.76174 | AE23: =AE22 -> 75 | AF23: =(ASIN(AE23/AD23)) -> 0.2646186 | AG23: =DEGREES(AF23+ABS(AC23-Z23)) -> 15.391303 | AH23: =DEGREES(ATAN((Main!S23/2+Main!D23/2)/Main!C23)) -> 16.795377 | AI23: =A23 -> 21 | AJ23: =Main!S23*(G23-Main!T23)/G23/25 -> 1.7691551
A24: 22 | B24: ='MDSL cloud import'!C24 -> 242.8831 | C24: ='MDSL cloud import'!D24 -> 107.2608 | D24: ='MDSL cloud import'!E24 -> -23.5096 | E24: =SQRT((B24^2)+(C24^2)+(D24^2)) -> 266.55165 | F24: =SQRT((1)+((C24/B24)^2)+(D24/B24)^2) -> 1.0974483 | G24: =Main!C24 -> 80.058832 | H24: =E24+G24+Main!T24 -> 356.61048 | I24: =H24/F24*SIGN(B24) -> 324.94513 | J24: =I24*C24/B24 -> 143.50061 | K24: =I24*D24/B24 -> -31.452703 | L24: =(H24-Main!T24)/F24*SIGN(B24) -> 315.83308 | M24: =L24*C24/B24 -> 139.4766 | N24: =L24*D24/B24 -> -30.570712 | O24: =(H24)/2 -> 178.30524 | P24: =O24/F24*SIGN(B24) -> 162.47256 | Q24: =P24*C24/B24 -> 71.750307 | R24: =P24*D24/B24 -> -15.726351 | S24: =DEGREES(ATAN((ABS(C24))/(ABS(B24)))) -> 23.826968 | T24: =S24+180 -> 203.82697 | U24: =90-DEGREES(ACOS(ABS(D24/E24))) -> 5.0600078 | V24: =-U24 -> -5.0600078 | X24: =SQRT(SUMSQ(B24,C24)) -> 265.51286 | Y24: =(ATAN2(B24,C24)) -> 0.41585905 | Z24: =(ATAN2(X24,D24)) -> -0.088313795 | AA24: =-Main!D24/2*SIN(ABS(Z24))+X24 -> 265.41143 | AB24: =Main!D24/2*COS(ABS(Z24))*SIGN(Z24)+D24 -> -24.655118 | AC24: =ATAN2(AA24,AB24) -> -0.09262813 | AD24: =SQRT(SUMSQ(AA24,AB24)) -> 266.55413 | AE24: =AE23 -> 75 | AF24: =(ASIN(AE24/AD24)) -> 0.28522018 | AG24: =DEGREES(AF24+ABS(AC24-Z24)) -> 16.589106 | AH24: =DEGREES(ATAN((Main!S24/2+Main!D24/2)/Main!C24)) -> 18.088839 | AI24: =A24 -> 22 | AJ24: =Main!S24*(G24-Main!T24)/G24/25 -> 1.7501837
A25: 23 | B25: ='MDSL cloud import'!C25 -> 201.3326 | C25: ='MDSL cloud import'!D25 -> 136.87 | D25: ='MDSL cloud import'!E25 -> -23.62 | E25: =SQRT((B25^2)+(C25^2)+(D25^2)) -> 244.59378 | F25: =SQRT((1)+((C25/B25)^2)+(D25/B25)^2) -> 1.2148742 | G25: =Main!C25 -> 72.859398 | H25: =E25+G25+Main!T25 -> 327.45318 | I25: =H25/F25*SIGN(B25) -> 269.5367 | J25: =I25*C25/B25 -> 183.23653 | K25: =I25*D25/B25 -> -31.621589 | L25: =(H25-Main!T25)/F25*SIGN(B25) -> 261.30539 | M25: =L25*C25/B25 -> 177.64073 | N25: =L25*D25/B25 -> -30.655907 | O25: =(H25)/2 -> 163.72659 | P25: =O25/F25*SIGN(B25) -> 134.76835 | Q25: =P25*C25/B25 -> 91.618267 | R25: =P25*D25/B25 -> -15.810795 | S25: =DEGREES(ATAN((ABS(C25))/(ABS(B25)))) -> 34.208663 | T25: =S25+180 -> 214.20866 | U25: =90-DEGREES(ACOS(ABS(D25/E25))) -> 5.5415906 | V25: =-U25 -> -5.5415906 | X25: =SQRT(SUMSQ(B25,C25)) -> 243.45064 | Y25: =(ATAN2(B25,C25)) -> 0.59705381 | Z25: =(ATAN2(X25,D25)) -> -0.096719001 | AA25: =-Main!D25/2*SIN(ABS(Z25))+X25 -> 243.33958 | AB25: =Main!D25/2*COS(ABS(Z25))*SIGN(Z25)+D25 -> -24.764625 | AC25: =ATAN2(AA25,AB25) -> -0.10142064 | AD25: =SQRT(SUMSQ(AA25,AB25)) -> 244.59648 | AE25: =AE24 -> 75 | AF25: =(ASIN(AE25/AD25)) -> 0.31164779 | AG25: =DEGREES(AF25+ABS(AC25-Z25)) -> 18.125487 | AH25: =DEGREES(ATAN((Main!S25/2+Main!D25/2)/Main!C25)) -> 19.743593 | AI25: =A25 -> 23 | AJ25: =Main!S25*(G25-Main!T25)/G25/25 -> 1.7254987
A26: 24 | B26: ='MDSL cloud import'!C26 -> 155.0181 | C26: ='MDSL cloud import'!D26 -> 158.4473 | D26: ='MDSL cloud import'!E26 -> -23.7553 | E26: =SQRT((B26^2)+(C26^2)+(D26^2)) -> 222.93603 | F26: =SQRT((1)+((C26/B26)^2)+(D26/B26)^2) -> 1.438129 | G26: =Main!C26 -> 65.690837 | H26: =E26+G26+Main!T26 -> 298.62686 | I26: =H26/F26*SIGN(B26) -> 207.64956 | J26: =I26*C26/B26 -> 212.24304 | K26: =I26*D26/B26 -> -31.820656 | L26: =(H26-Main!T26)/F26*SIGN(B26) -> 200.69609 | M26: =L26*C26/B26 -> 205.13574 | N26: =L26*D26/B26 -> -30.755091 | O26: =(H26)/2 -> 149.31343 | P26: =O26/F26*SIGN(B26) -> 103.82478 | Q26: =P26*C26/B26 -> 106.12152 | R26: =P26*D26/B26 -> -15.910328 | S26: =DEGREES(ATAN((ABS(C26))/(ABS(B26)))) -> 45.62677 | T26: =S26+180 -> 225.62677 | U26: =90-DEGREES(ACOS(ABS(D26/E26))) -> 6.116855 | V26: =-U26 -> -6.116855 | X26: =SQRT(SUMSQ(B26,C26)) -> 221.66677 | Y26: =(ATAN2(B26,C26)) -> 0.79633737 | Z26: =(ATAN2(X26,D26)) -> -0.10675926 | AA26: =-Main!D26/2*SIN(ABS(Z26))+X26 -> 221.54423 | AB26: =Main!D26/2*COS(ABS(Z26))*SIGN(Z26)+D26 -> -24.898753 | AC26: =ATAN2(AA26,AB26) -> -0.11191764 | AD26: =SQRT(SUMSQ(AA26,AB26)) -> 222.93899 | AE26: =AE25 -> 75 | AF26: =(ASIN(AE26/AD26)) -> 0.3431073 | AG26: =DEGREES(AF26+ABS(AC26-Z26)) -> 19.954154 | AH26: =DEGREES(ATAN((Main!S26/2+Main!D26/2)/Main!C26)) -> 21.706356 | AI26: =A26 -> 24 | AJ26: =Main!S26*(G26-Main!T26)/G26/25 -> 1.6955435
A27: 25 | B27: ='MDSL cloud import'!C27 -> 106.2709 | C27: ='MDSL cloud import'!D27 -> 171.9591 | D27: ='MDSL cloud import'!E27 -> -23.9071 | E27: =SQRT((B27^2)+(C27^2)+(D27^2)) -> 203.55585 | F27: =SQRT((1)+((C27/B27)^2)+(D27/B27)^2) -> 1.915443 | G27: =Main!C27 -> 59.199306 | H27: =E27+G27+Main!T27 -> 272.75516 | I27: =H27/F27*SIGN(B27) -> 142.39795 | J27: =I27*C27/B27 -> 230.41701 | K27: =I27*D27/B27 -> -32.034377 | L27: =(H27-Main!T27)/F27*SIGN(B27) -> 137.17723 | M27: =L27*C27/B27 -> 221.96925 | N27: =L27*D27/B27 -> -30.859903 | O27: =(H27)/2 -> 136.37758 | P27: =O27/F27*SIGN(B27) -> 71.198975 | Q27: =P27*C27/B27 -> 115.20851 | R27: =P27*D27/B27 -> -16.017188 | S27: =DEGREES(ATAN((ABS(C27))/(ABS(B27)))) -> 58.283892 | T27: =S27+180 -> 238.28389 | U27: =90-DEGREES(ACOS(ABS(D27/E27))) -> 6.7448059 | V27: =-U27 -> -6.7448059 | X27: =SQRT(SUMSQ(B27,C27)) -> 202.14707 | Y27: =(ATAN2(B27,C27)) -> 1.0172458 | Z27: =(ATAN2(X27,D27)) -> -0.11771907 | AA27: =-Main!D27/2*SIN(ABS(Z27))+X27 -> 202.012 | AB27: =Main!D27/2*COS(ABS(Z27))*SIGN(Z27)+D27 -> -25.049141 | AC27: =ATAN2(AA27,AB27) -> -0.12336857 | AD27: =SQRT(SUMSQ(AA27,AB27)) -> 203.5591 | AE27: =AE26 -> 75 | AF27: =(ASIN(AE27/AD27)) -> 0.37733403 | AG27: =DEGREES(AF27+ABS(AC27-Z27)) -> 21.94334 | AH27: =DEGREES(ATAN((Main!S27/2+Main!D27/2)/Main!C27)) -> 23.832397 | AI27: =A27 -> 25 | AJ27: =Main!S27*(G27-Main!T27)/G27/25 -> 1.6621582
A28: 26 | B28: ='MDSL cloud import'!C28 -> 56.74056 | C28: ='MDSL cloud import'!D28 -> 177.7703 | D28: ='MDSL cloud import'!E28 -> -24.0565 | E28: =SQRT((B28^2)+(C28^2)+(D28^2)) -> 188.15017 | F28: =SQRT((1)+((C28/B28)^2)+(D28/B28)^2) -> 3.3159731 | G28: =Main!C28 -> 53.969215 | H28: =E28+G28+Main!T28 -> 252.11938 | I28: =H28/F28*SIGN(B28) -> 76.031795 | J28: =I28*C28/B28 -> 238.21046 | K28: =I28*D28/B28 -> -32.235474 | L28: =(H28-Main!T28)/F28*SIGN(B28) -> 73.016089 | M28: =L28*C28/B28 -> 228.76214 | N28: =L28*D28/B28 -> -30.956895 | O28: =(H28)/2 -> 126.05969 | P28: =O28/F28*SIGN(B28) -> 38.015897 | Q28: =P28*C28/B28 -> 119.10523 | R28: =P28*D28/B28 -> -16.117737 | S28: =DEGREES(ATAN((ABS(C28))/(ABS(B28)))) -> 72.298005 | T28: =S28+180 -> 252.29801 | U28: =90-DEGREES(ACOS(ABS(D28/E28))) -> 7.3458305 | V28: =-U28 -> -7.3458305 | X28: =SQRT(SUMSQ(B28,C28)) -> 186.60592 | Y28: =(ATAN2(B28,C28)) -> 1.2618382 | Z28: =(ATAN2(X28,D28)) -> -0.12820893 | AA28: =-Main!D28/2*SIN(ABS(Z28))+X28 -> 186.45889 | AB28: =Main!D28/2*COS(ABS(Z28))*SIGN(Z28)+D28 -> -25.197061 | AC28: =ATAN2(AA28,AB28) -> -0.13432099 | AD28: =SQRT(SUMSQ(AA28,AB28)) -> 188.15368 | AE28: =AE27 -> 75 | AF28: =(ASIN(AE28/AD28)) -> 0.41000108 | AG28: =DEGREES(AF28+ABS(AC28-Z28)) -> 23.841527 | AH28: =DEGREES(ATAN((Main!S28/2+Main!D28/2)/Main!C28)) -> 25.851835 | AI28: =A28 -> 26 | AJ28: =Main!S28*(G28-Main!T28)/G28/25 -> 1.6294184
A29: 27 | B29: ='MDSL cloud import'!C29 -> 7.351419 | C29: ='MDSL cloud import'!D29 -> 176.2461 | D29: ='MDSL cloud import'!E29 -> -24.1728 | E29: =SQRT((B29^2)+(C29^2)+(D29^2)) -> 178.0479 | F29: =SQRT((1)+((C29/B29)^2)+(D29/B29)^2) -> 24.219528 | G29: =Main!C29 -> 50.495914 | H29: =E29+G29+Main!T29 -> 238.54382 | I29: =H29/F29*SIGN(B29) -> 9.8492345 | J29: =I29*C29/B29 -> 236.12981 | K29: =I29*D29/B29 -> -32.386071 | L29: =(H29-Main!T29)/F29*SIGN(B29) -> 9.4363445 | M29: =L29*C29/B29 -> 226.23101 | N29: =L29*D29/B29 -> -31.028414 | O29: =(H29)/2 -> 119.27191 | P29: =O29/F29*SIGN(B29) -> 4.9246172 | Q29: =P29*C29/B29 -> 118.0649 | R29: =P29*D29/B29 -> -16.193035 | S29: =DEGREES(ATAN((ABS(C29))/(ABS(B29)))) -> 87.611514 | T29: =S29+180 -> 267.61151 | U29: =90-DEGREES(ACOS(ABS(D29/E29))) -> 7.8028996 | V29: =-U29 -> -7.8028996 | X29: =SQRT(SUMSQ(B29,C29)) -> 176.39935 | Y29: =(ATAN2(B29,C29)) -> 1.5291094 | Z29: =(ATAN2(X29,D29)) -> -0.13618629 | AA29: =-Main!D29/2*SIN(ABS(Z29))+X29 -> 176.24322 | AB29: =Main!D29/2*COS(ABS(Z29))*SIGN(Z29)+D29 -> -25.312152 | AC29: =ATAN2(AA29,AB29) -> -0.14264513 | AD29: =SQRT(SUMSQ(AA29,AB29)) -> 178.05162 | AE29: =AE28 -> 75 | AF29: =(ASIN(AE29/AD29)) -> 0.43479686 | AG29: =DEGREES(AF29+ABS(AC29-Z29)) -> 25.28209 | AH29: =DEGREES(ATAN((Main!S29/2+Main!D29/2)/Main!C29)) -> 27.377998 | AI29: =A29 -> 27 | AJ29: =Main!S29*(G29-Main!T29)/G29/25 -> 1.6039283
A30: 28 | B30: ='MDSL cloud import'!C30 -> -41.7583 | C30: ='MDSL cloud import'!D30 -> 167.3279 | D30: ='MDSL cloud import'!E30 -> -24.2224 | E30: =SQRT((B30^2)+(C30^2)+(D30^2)) -> 174.15254 | F30: =SQRT((1)+((C30/B30)^2)+(D30/B30)^2) -> 4.1704892 | G30: =Main!C30 -> 49.145502 | H30: =E30+G30+Main!T30 -> 233.29804 | I30: =H30/F30*SIGN(B30) -> -55.94021 | J30: =I30*C30/B30 -> 224.15563 | K30: =I30*D30/B30 -> -32.448786 | L30: =(H30-Main!T30)/F30*SIGN(B30) -> -53.54241 | M30: =L30*C30/B30 -> 214.5475 | N30: =L30*D30/B30 -> -31.057913 | O30: =(H30)/2 -> 116.64902 | P30: =O30/F30*SIGN(B30) -> -27.970105 | Q30: =P30*C30/B30 -> 112.07781 | R30: =P30*D30/B30 -> -16.224393 | S30: =DEGREES(ATAN((ABS(C30))/(ABS(B30)))) -> 75.987503 | T30: =-S30 -> -75.987503 | U30: =90-DEGREES(ACOS(ABS(D30/E30))) -> 7.9950336 | V30: =-U30 -> -7.9950336 | X30: =SQRT(SUMSQ(B30,C30)) -> 172.4598 | Y30: =(ATAN2(B30,C30)) -> 1.8153605 | Z30: =(ATAN2(X30,D30)) -> -0.13953966 | AA30: =-Main!D30/2*SIN(ABS(Z30))+X30 -> 172.29985 | AB30: =Main!D30/2*COS(ABS(Z30))*SIGN(Z30)+D30 -> -25.361222 | AC30: =ATAN2(AA30,AB30) -> -0.14614297 | AD30: =SQRT(SUMSQ(AA30,AB30)) -> 174.15633 | AE30: =AE29 -> 75 | AF30: =(ASIN(AE30/AD30)) -> 0.44521015 | AG30: =DEGREES(AF30+ABS(AC30-Z30)) -> 25.887005 | AH30: =DEGREES(ATAN((Main!S30/2+Main!D30/2)/Main!C30)) -> 28.017151 | AI30: =A30 -> 28 | AJ30: =Main!S30*(G30-Main!T30)/G30/25 -> 1.5930452
A31: 29 | B31: ='MDSL cloud import'!C31 -> -89.0623 | C31: ='MDSL cloud import'!D31 -> 150.8126 | D31: ='MDSL cloud import'!E31 -> -24.1883 | E31: =SQRT((B31^2)+(C31^2)+(D31^2)) -> 176.80952 | F31: =SQRT((1)+((C31/B31)^2)+(D31/B31)^2) -> 1.9852342 | G31: =Main!C31 -> 50.067327 | H31: =E31+G31+Main!T31 -> 236.87685 | I31: =H31/F31*SIGN(B31) -> -119.31935 | J31: =I31*C31/B31 -> 202.04802 | K31: =I31*D31/B31 -> -32.405768 | L31: =(H31-Main!T31)/F31*SIGN(B31) -> -114.28216 | M31: =L31*C31/B31 -> 193.51835 | N31: =L31*D31/B31 -> -31.037725 | O31: =(H31)/2 -> 118.43843 | P31: =O31/F31*SIGN(B31) -> -59.659674 | Q31: =P31*C31/B31 -> 101.02401 | R31: =P31*D31/B31 -> -16.202884 | S31: =DEGREES(ATAN((ABS(C31))/(ABS(B31)))) -> 59.436048 | T31: =-S31 -> -59.436048 | U31: =90-DEGREES(ACOS(ABS(D31/E31))) -> 7.8629658 | V31: =-U31 -> -7.8629658 | X31: =SQRT(SUMSQ(B31,C31)) -> 175.14718 | Y31: =(ATAN2(B31,C31)) -> 2.1042379 | Z31: =(ATAN2(X31,D31)) -> -0.13723464 | AA31: =-Main!D31/2*SIN(ABS(Z31))+X31 -> 174.98985 | AB31: =Main!D31/2*COS(ABS(Z31))*SIGN(Z31)+D31 -> -25.327488 | AC31: =ATAN2(AA31,AB31) -> -0.14373872 | AD31: =SQRT(SUMSQ(AA31,AB31)) -> 176.81326 | AE31: =AE30 -> 75 | AF31: =(ASIN(AE31/AD31)) -> 0.43805214 | AG31: =DEGREES(AF31+ABS(AC31-Z31)) -> 25.471195 | AH31: =DEGREES(ATAN((Main!S31/2+Main!D31/2)/Main!C31)) -> 27.577917 | AI31: =A31 -> 29 | AJ31: =Main!S31*(G31-Main!T31)/G31/25 -> 1.6005379
A32: 30 | B32: ='MDSL cloud import'!C32 -> -132.361 | C32: ='MDSL cloud import'!D32 -> 126.955 | D32: ='MDSL cloud import'!E32 -> -24.0912 | E32: =SQRT((B32^2)+(C32^2)+(D32^2)) -> 184.97944 | F32: =SQRT((1)+((C32/B32)^2)+(D32/B32)^2) -> 1.3975373 | G32: =Main!C32 -> 52.883244 | H32: =E32+G32+Main!T32 -> 247.86268 | I32: =H32/F32*SIGN(B32) -> -177.35675 | J32: =I32*C32/B32 -> 170.113 | K32: =I32*D32/B32 -> -32.280936 | L32: =(H32-Main!T32)/F32*SIGN(B32) -> -170.20131 | M32: =L32*C32/B32 -> 163.2498 | N32: =L32*D32/B32 -> -30.978564 | O32: =(H32)/2 -> 123.93134 | P32: =O32/F32*SIGN(B32) -> -88.678376 | Q32: =P32*C32/B32 -> 85.056499 | R32: =P32*D32/B32 -> -16.140468 | S32: =DEGREES(ATAN((ABS(C32))/(ABS(B32)))) -> 43.805719 | T32: =-S32 -> -43.805719 | U32: =90-DEGREES(ACOS(ABS(D32/E32))) -> 7.4832982 | V32: =-U32 -> -7.4832982 | X32: =SQRT(SUMSQ(B32,C32)) -> 183.40394 | Y32: =(ATAN2(B32,C32)) -> 2.3770386 | Z32: =(ATAN2(X32,D32)) -> -0.13060819 | AA32: =-Main!D32/2*SIN(ABS(Z32))+X32 -> 183.25417 | AB32: =Main!D32/2*COS(ABS(Z32))*SIGN(Z32)+D32 -> -25.231405 | AC32: =ATAN2(AA32,AB32) -> -0.13682502 | AD32: =SQRT(SUMSQ(AA32,AB32)) -> 184.98301 | AE32: =AE31 -> 75 | AF32: =(ASIN(AE32/AD32)) -> 0.417463 | AG32: =DEGREES(AF32+ABS(AC32-Z32)) -> 24.275066 | AH32: =DEGREES(ATAN((Main!S32/2+Main!D32/2)/Main!C32)) -> 26.31173 | AI32: =A32 -> 30 | AJ32: =Main!S32*(G32-Main!T32)/G32/25 -> 1.6218084
A33: 31 | B33: ='MDSL cloud import'!C33 -> -170.499 | C33: ='MDSL cloud import'!D33 -> 95.57272 | D33: ='MDSL cloud import'!E33 -> -23.9678 | E33: =SQRT((B33^2)+(C33^2)+(D33^2)) -> 196.9226 | F33: =SQRT((1)+((C33/B33)^2)+(D33/B33)^2) -> 1.154978 | G33: =Main!C33 -> 56.956126 | H33: =E33+G33+Main!T33 -> 263.87872 | I33: =H33/F33*SIGN(B33) -> -228.47077 | J33: =I33*C33/B33 -> 128.06863 | K33: =I33*D33/B33 -> -32.117149 | L33: =(H33-Main!T33)/F33*SIGN(B33) -> -219.8126 | M33: =L33*C33/B33 -> 123.21532 | N33: =L33*D33/B33 -> -30.900031 | O33: =(H33)/2 -> 131.93936 | P33: =O33/F33*SIGN(B33) -> -114.23539 | Q33: =P33*C33/B33 -> 64.034315 | R33: =P33*D33/B33 -> -16.058575 | S33: =DEGREES(ATAN((ABS(C33))/(ABS(B33)))) -> 29.272684 | T33: =-S33 -> -29.272684 | U33: =90-DEGREES(ACOS(ABS(D33/E33))) -> 6.9909046 | V33: =-U33 -> -6.9909046 | X33: =SQRT(SUMSQ(B33,C33)) -> 195.45857 | Y33: =(ATAN2(B33,C33)) -> 2.6306879 | Z33: =(ATAN2(X33,D33)) -> -0.1220143 | AA33: =-Main!D33/2*SIN(ABS(Z33))+X33 -> 195.3186 | AB33: =Main!D33/2*COS(ABS(Z33))*SIGN(Z33)+D33 -> -25.10925 | AC33: =ATAN2(AA33,AB33) -> -0.1278541 | AD33: =SQRT(SUMSQ(AA33,AB33)) -> 196.92595 | AE33: =AE32 -> 75 | AF33: =(ASIN(AE33/AD33)) -> 0.39071952 | AG33: =DEGREES(AF33+ABS(AC33-Z33)) -> 22.721175 | AH33: =DEGREES(ATAN((Main!S33/2+Main!D33/2)/Main!C33)) -> 24.661054 | AI33: =A33 -> 31 | AJ33: =Main!S33*(G33-Main!T33)/G33/25 -> 1.6488525
A34: 32 | B34: ='MDSL cloud import'!C34 -> -201.258 | C34: ='MDSL cloud import'!D34 -> 56.97774 | D34: ='MDSL cloud import'!E34 -> -23.8485 | E34: =SQRT((B34^2)+(C34^2)+(D34^2)) -> 210.52315 | F34: =SQRT((1)+((C34/B34)^2)+(D34/B34)^2) -> 1.0460362 | G34: =Main!C34 -> 61.542947 | H34: =E34+G34+Main!T34 -> 282.0661 | I34: =H34/F34*SIGN(B34) -> -269.65233 | J34: =I34*C34/B34 -> 76.340719 | K34: =I34*D34/B34 -> -31.953034 | L34: =(H34-Main!T34)/F34*SIGN(B34) -> -260.09243 | M34: =L34*C34/B34 -> 73.634236 | N34: =L34*D34/B34 -> -30.820213 | O34: =(H34)/2 -> 141.03305 | P34: =O34/F34*SIGN(B34) -> -134.82617 | Q34: =P34*C34/B34 -> 38.17036 | R34: =P34*D34/B34 -> -15.976517 | S34: =DEGREES(ATAN((ABS(C34))/(ABS(B34)))) -> 15.807239 | T34: =-S34 -> -15.807239 | U34: =90-DEGREES(ACOS(ABS(D34/E34))) -> 6.5045479 | V34: =-U34 -> -6.5045479 | X34: =SQRT(SUMSQ(B34,C34)) -> 209.16798 | Y34: =(ATAN2(B34,C34)) -> 2.8657043 | Z34: =(ATAN2(X34,D34)) -> -0.11352578 | AA34: =-Main!D34/2*SIN(ABS(Z34))+X34 -> 209.03771 | AB34: =Main!D34/2*COS(ABS(Z34))*SIGN(Z34)+D34 -> -24.991097 | AC34: =ATAN2(AA34,AB34) -> -0.1189883 | AD34: =SQRT(SUMSQ(AA34,AB34)) -> 210.52629 | AE34: =AE33 -> 75 | AF34: =(ASIN(AE34/AD34)) -> 0.36425154 | AG34: =DEGREES(AF34+ABS(AC34-Z34)) -> 21.183056 | AH34: =DEGREES(ATAN((Main!S34/2+Main!D34/2)/Main!C34)) -> 23.020956 | AI34: =A34 -> 32 | AJ34: =Main!S34*(G34-Main!T34)/G34/25 -> 1.6750237
A35: 33 | B35: ='MDSL cloud import'!C35 -> -221.948 | C35: ='MDSL cloud import'!D35 -> 12.56229 | D35: ='MDSL cloud import'!E35 -> -23.7509 | E35: =SQRT((B35^2)+(C35^2)+(D35^2)) -> 223.5684 | F35: =SQRT((1)+((C35/B35)^2)+(D35/B35)^2) -> 1.0073008 | G35: =Main!C35 -> 65.901303 | H35: =E35+G35+Main!T35 -> 299.46971 | I35: =H35/F35*SIGN(B35) -> -297.29918 | J35: =I35*C35/B35 -> 16.827178 | K35: =I35*D35/B35 -> -31.814313 | L35: =(H35-Main!T35)/F35*SIGN(B35) -> -287.37166 | M35: =L35*C35/B35 -> 16.265279 | N35: =L35*D35/B35 -> -30.751958 | O35: =(H35)/2 -> 149.73485 | P35: =O35/F35*SIGN(B35) -> -148.64959 | Q35: =P35*C35/B35 -> 8.413589 | R35: =P35*D35/B35 -> -15.907156 | S35: =DEGREES(ATAN((ABS(C35))/(ABS(B35)))) -> 3.2394933 | T35: =-S35 -> -3.2394933 | U35: =90-DEGREES(ACOS(ABS(D35/E35))) -> 6.0983534 | V35: =-U35 -> -6.0983534 | X35: =SQRT(SUMSQ(B35,C35)) -> 222.30323 | Y35: =(ATAN2(B35,C35)) -> 3.0850528 | Z35: =(ATAN2(X35,D35)) -> -0.10643635 | AA35: =-Main!D35/2*SIN(ABS(Z35))+X35 -> 222.18106 | AB35: =Main!D35/2*COS(ABS(Z35))*SIGN(Z35)+D35 -> -24.894392 | AC35: =ATAN2(AA35,AB35) -> -0.11158014 | AD35: =SQRT(SUMSQ(AA35,AB35)) -> 223.57136 | AE35: =AE34 -> 75 | AF35: =(ASIN(AE35/AD35)) -> 0.34209705 | AG35: =DEGREES(AF35+ABS(AC35-Z35)) -> 19.895435 | AH35: =DEGREES(ATAN((Main!S35/2+Main!D35/2)/Main!C35)) -> 21.64345 | AI35: =A35 -> 33 | AJ35: =Main!S35*(G35-Main!T35)/G35/25 -> 1.6965159
A36: 34 | B36: ='MDSL cloud import'!C36 -> -230.423 | C36: ='MDSL cloud import'!D36 -> -35.1111 | D36: ='MDSL cloud import'!E36 -> -23.6806 | E36: =SQRT((B36^2)+(C36^2)+(D36^2)) -> 234.28256 | F36: =SQRT((1)+((C36/B36)^2)+(D36/B36)^2) -> 1.0167499 | G36: =Main!C36 -> 69.456102 | H36: =E36+G36+Main!T36 -> 313.73866 | I36: =H36/F36*SIGN(B36) -> -308.57014 | J36: =I36*C36/B36 -> -47.018905 | K36: =I36*D36/B36 -> -31.711792 | L36: =(H36-Main!T36)/F36*SIGN(B36) -> -298.73488 | M36: =L36*C36/B36 -> -45.520241 | N36: =L36*D36/B36 -> -30.701021 | O36: =(H36)/2 -> 156.86933 | P36: =O36/F36*SIGN(B36) -> -154.28507 | Q36: =P36*C36/B36 -> -23.509453 | R36: =P36*D36/B36 -> -15.855896 | S36: =DEGREES(ATAN((ABS(C36))/(ABS(B36)))) -> 8.6638982 | T36: =S36 -> 8.6638982 | U36: =90-DEGREES(ACOS(ABS(D36/E36))) -> 5.8011976 | V36: =-U36 -> -5.8011976 | X36: =SQRT(SUMSQ(B36,C36)) -> 233.08271 | Y36: =(ATAN2(B36,C36)) -> -2.9903791 | Z36: =(ATAN2(X36,D36)) -> -0.10125 | AA36: =-Main!D36/2*SIN(ABS(Z36))+X36 -> 232.96647 | AB36: =Main!D36/2*COS(ABS(Z36))*SIGN(Z36)+D36 -> -24.82471 | AC36: =ATAN2(AA36,AB36) -> -0.10615856 | AD36: =SQRT(SUMSQ(AA36,AB36)) -> 234.28538 | AE36: =AE35 -> 75 | AF36: =(ASIN(AE36/AD36)) -> 0.32585868 | AG36: =DEGREES(AF36+ABS(AC36-Z36)) -> 18.951567 | AH36: =DEGREES(ATAN((Main!S36/2+Main!D36/2)/Main!C36)) -> 20.631195 | AI36: =A36 -> 34 | AJ36: =Main!S36*(G36-Main!T36)/G36/25 -> 1.7120483
A37: 35 | B37: ='MDSL cloud import'!C37 -> -225.927 | C37: ='MDSL cloud import'!D37 -> -82.9365 | D37: ='MDSL cloud import'!E37 -> -23.6357 | E37: =SQRT((B37^2)+(C37^2)+(D37^2)) -> 241.82663 | F37: =SQRT((1)+((C37/B37)^2)+(D37/B37)^2) -> 1.0703751 | G37: =Main!C37 -> 71.94765 | H37: =E37+G37+Main!T37 -> 323.77428 | I37: =H37/F37*SIGN(B37) -> -302.48675 | J37: =I37*C37/B37 -> -111.04114 | K37: =I37*D37/B37 -> -31.645116 | L37: =(H37-Main!T37)/F37*SIGN(B37) -> -293.14423 | M37: =L37*C37/B37 -> -107.61156 | N37: =L37*D37/B37 -> -30.667734 | O37: =(H37)/2 -> 161.88714 | P37: =O37/F37*SIGN(B37) -> -151.24338 | Q37: =P37*C37/B37 -> -55.520572 | R37: =P37*D37/B37 -> -15.822558 | S37: =DEGREES(ATAN((ABS(C37))/(ABS(B37)))) -> 20.157895 | T37: =S37 -> 20.157895 | U37: =90-DEGREES(ACOS(ABS(D37/E37))) -> 5.6089409 | V37: =-U37 -> -5.6089409 | X37: =SQRT(SUMSQ(B37,C37)) -> 240.6688 | Y37: =(ATAN2(B37,C37)) -> -2.789771 | Z37: =(ATAN2(X37,D37)) -> -0.097894487 | AA37: =-Main!D37/2*SIN(ABS(Z37))+X37 -> 240.5564 | AB37: =Main!D37/2*COS(ABS(Z37))*SIGN(Z37)+D37 -> -24.780194 | AC37: =ATAN2(AA37,AB37) -> -0.10264992 | AD37: =SQRT(SUMSQ(AA37,AB37)) -> 241.82936 | AE37: =AE36 -> 75 | AF37: =(ASIN(AE37/AD37)) -> 0.31533612 | AG37: =DEGREES(AF37+ABS(AC37-Z37)) -> 18.339895 | AH37: =DEGREES(ATAN((Main!S37/2+Main!D37/2)/Main!C37)) -> 19.974116 | AI37: =A37 -> 35 | AJ37: =Main!S37*(G37-Main!T37)/G37/25 -> 1.7220201
